Workbook

Sheet Reproting_ERPALIN
L1: Parametres | O1: Chiffre d'affaires | T1: Marge brute hors transport, hors frais amazon | Z1: Marge brute incluant transport, hors frais amazon | AF1: Marge brute incluant transport, incluant frais amazon
A2: Produit / Service | B2: SKU du produit | C2: Fournisseur | D2: Mois,année | E2: Quantité | F2: Total HT | G2: Coût de livraison HT | H2: Bénéfice | I2: Taux de marque | J2: Livraison: Pays | K2: Référence externe | L2: Mois | M2: Année | N2: Date en nombre | O2: CA unitaire, hors transport | P2: CA ligne de produit, hors transport | Q2: CA unitaire transport HT | R2: CA unitaire, avec transport | S2: CA ligne produit, avec transport | T2: COGS unitaire, hors transport | U2: Marge brute unitaire, hors cout de transport | V2: Marge brute ligne produit, hors cout de transport | W2: GLS | X2: SCHENKER | Y2: GOFO | Z2: Total transport par commande (€) | AA2: Coût de transport par ligne de produit HT | AB2: Coût de transport unitaire HT | AC2: Marge unitaire incluant transport (€ HT) | AD2: Taux de marge, incluant transport (%) | AE2: Marge ligne de produit incluant transport, hors amazon, HT | AF2: Frais amazon par commande HT | AG2: Frais amazon par ligne de produit HT | AH2: Frais amazon unitaire HT | AI2: Marge incluant transport et frais amazon (€ HT) | AJ2: Marge incluant transport et frais amazon (%) | AK2: Marge ligne produit incluant transport et frais amazon (€ HT)
A3: Abena - Couches adulte intraversables Maternity Pad Super - Sachet de 15 pièces | B3: 1000022654 | C3: Abena | D3: 2026-01-01 | E3: 30 | F3: 14.79 | G3: 0 | H3: 10.55 | I3: 71.3 | J3: FR | K3: 408-9873588-3982738 | L3: =MONTH(D3) -> 1 | M3: =YEAR(D3) -> 2026 | N3: =D3*1 -> 46023 | O3: =F3/E3 -> 0.493 | P3: =O3*E3 -> 14.79 | Q3: =G3/E3 -> 0 | R3: =O3+Q3 -> 0.493 | S3: =R3*E3 -> 14.79 | T3: =-(F3-H3)/E3 -> -0.14133333 | U3: =R3+T3 -> 0.35166667 | V3: =U3*E3 -> 10.55 | W3: =SUMIF(GLS!B:B,K3,GLS!C:C) -> 5.48 | Z3: =-IF(W3+X3+Y3=0,"à vérifier",W3+X3+Y3) -> -5.48 | AA3: =IFERROR((SUMIF($K:$K,K3,$Z:$Z)/COUNTIF($K:$K,K3))*E3/SUMIF($K:$K,K3,$E:$E),0) -> -5.48 | AB3: =AA3/E3 -> -0.18266667 | AC3: =AB3+U3 -> 0.169 | AD3: =AC3/R3 -> 0.34279919 | AE3: =AC3*E3 -> 5.07 | AF3: =IFERROR(-ABS(INDEX('frais amazon 011225-150326'!H:H,MATCH(Reproting_ERPALIN!K3,'frais amazon 011225-150326'!D:D,0))/1.2),"Commande hors la France") -> -2.75 | AG3: =IFERROR(AF3*E3/SUMIF($K:$K,K3,$E:$E),0) -> -2.75 | AH3: =AG3/E3 -> -0.091666667 | AI3: =AH3+AC3 -> 0.077333333 | AJ3: =AI3/R3 -> 0.15686275 | AK3: =AI3*E3 -> 2.32
A4: Aiguille hypodermique à usage unique non sécurisée 21G, 0,8 mm x 50 mm | B4: IN-08X50 | C4: ZARYS International Group sp. z o.o. sp.k. | D4: 2026-01-01 | E4: 100 | F4: 12.98 | G4: 4.99 | H4: 11.52 | I4: 88.75 | J4: FR | K4: 408-9840795-1860306 | L4: =MONTH(D4) -> 1 | M4: =YEAR(D4) -> 2026 | N4: =D4*1 -> 46023 | O4: =F4/E4 -> 0.1298 | P4: =O4*E4 -> 12.98 | Q4: =G4/E4 -> 0.0499 | R4: =O4+Q4 -> 0.1797 | S4: =R4*E4 -> 17.97 | T4: =-(F4-H4)/E4 -> -0.0146 | U4: =R4+T4 -> 0.1651 | V4: =U4*E4 -> 16.51 | W4: =SUMIF(GLS!B:B,K4,GLS!C:C) -> 5.25 | Z4: =-IF(W4+X4+Y4=0,"à vérifier",W4+X4+Y4) -> -5.25 | AA4: =IFERROR((SUMIF($K:$K,K4,$Z:$Z)/COUNTIF($K:$K,K4))*E4/SUMIF($K:$K,K4,$E:$E),0) -> -5.25 | AB4: =AA4/E4 -> -0.0525 | AC4: =AB4+U4 -> 0.1126 | AD4: =AC4/R4 -> 0.62659989 | AE4: =AC4*E4 -> 11.26 | AF4: =IFERROR(-ABS(INDEX('frais amazon 011225-150326'!H:H,MATCH(Reproting_ERPALIN!K4,'frais amazon 011225-150326'!D:D,0))/1.2),"Commande hors la France") -> -3.3416667 | AG4: =IFERROR(AF4*E4/SUMIF($K:$K,K4,$E:$E),0) -> -3.3416667 | AH4: =AG4/E4 -> -0.033416667 | AI4: =AH4+AC4 -> 0.079183333 | AJ4: =AI4/R4 -> 0.44064181 | AK4: =AI4*E4 -> 7.9183333
A5: Aiguille hypodermique à usage unique non sécurisée 25G, 0,5 mm x 40 mm | B5: IN-05X40 | C5: ZARYS International Group sp. z o.o. sp.k. | D5: 2025-12-01 | E5: 200 | F5: 21.44 | G5: 4.99 | H5: 19.7 | I5: 91.88 | J5: FR | K5: 408-9832920-5794725 | L5: =MONTH(D5) -> 12 | M5: =YEAR(D5) -> 2025 | N5: =D5*1 -> 45992 | O5: =F5/E5 -> 0.1072 | P5: =O5*E5 -> 21.44 | Q5: =G5/E5 -> 0.02495 | R5: =O5+Q5 -> 0.13215 | S5: =R5*E5 -> 26.43 | T5: =-(F5-H5)/E5 -> -0.0087 | U5: =R5+T5 -> 0.12345 | V5: =U5*E5 -> 24.69 | W5: =SUMIF(GLS!B:B,K5,GLS!C:C) -> 5.25 | Z5: =-IF(W5+X5+Y5=0,"à vérifier",W5+X5+Y5) -> -5.25 | AA5: =IFERROR((SUMIF($K:$K,K5,$Z:$Z)/COUNTIF($K:$K,K5))*E5/SUMIF($K:$K,K5,$E:$E),0) -> -5.25 | AB5: =AA5/E5 -> -0.02625 | AC5: =AB5+U5 -> 0.0972 | AD5: =AC5/R5 -> 0.73552781 | AE5: =AC5*E5 -> 19.44 | AF5: =IFERROR(-ABS(INDEX('frais amazon 011225-150326'!H:H,MATCH(Reproting_ERPALIN!K5,'frais amazon 011225-150326'!D:D,0))/1.2),"Commande hors la France") -> -4.9083333 | AG5: =IFERROR(AF5*E5/SUMIF($K:$K,K5,$E:$E),0) -> -4.9083333 | AH5: =AG5/E5 -> -0.024541667 | AI5: =AH5+AC5 -> 0.072658333 | AJ5: =AI5/R5 -> 0.54981713 | AK5: =AI5*E5 -> 14.531667
A6: Seringue 3 pièces luer lock stérile 10ml, (Boite de 100 pièces) | B6: CH03010LL | C6: Vitrex Medical | D6: 2026-01-01 | E6: 1600 | F6: 210.72 | G6: 0 | H6: 117.92 | I6: 55.96 | J6: FR | K6: 408-9774002-0419541 | L6: =MONTH(D6) -> 1 | M6: =YEAR(D6) -> 2026 | N6: =D6*1 -> 46023 | O6: =F6/E6 -> 0.1317 | P6: =O6*E6 -> 210.72 | Q6: =G6/E6 -> 0 | R6: =O6+Q6 -> 0.1317 | S6: =R6*E6 -> 210.72 | T6: =-(F6-H6)/E6 -> -0.058 | U6: =R6+T6 -> 0.0737 | V6: =U6*E6 -> 117.92 | W6: =SUMIF(GLS!B:B,K6,GLS!C:C) -> 9.72 | Z6: =-IF(W6+X6+Y6=0,"à vérifier",W6+X6+Y6) -> -9.72 | AA6: =IFERROR((SUMIF($K:$K,K6,$Z:$Z)/COUNTIF($K:$K,K6))*E6/SUMIF($K:$K,K6,$E:$E),0) -> -9.72 | AB6: =AA6/E6 -> -0.006075 | AC6: =AB6+U6 -> 0.067625 | AD6: =AC6/R6 -> 0.5134776 | AE6: =AC6*E6 -> 108.2 | AF6: =IFERROR(-ABS(INDEX('frais amazon 011225-150326'!H:H,MATCH(Reproting_ERPALIN!K6,'frais amazon 011225-150326'!D:D,0))/1.2),"Commande hors la France") -> -39.05 | AG6: =IFERROR(AF6*E6/SUMIF($K:$K,K6,$E:$E),0) -> -39.05 | AH6: =AG6/E6 -> -0.02440625 | AI6: =AH6+AC6 -> 0.04321875 | AJ6: =AI6/R6 -> 0.32816059 | AK6: =AI6*E6 -> 69.15
A7: Aiguilles hypodermiques 1.20 x 50 mm, (Boite de 100 pièces) | B7: CH18200 | C7: Vitrex Medical | D7: 2026-01-01 | E7: 100 | F7: 10.93 | G7: 4.99 | H7: 9.07 | I7: 82.98 | J7: FR | K7: 408-9716015-9973139 | L7: =MONTH(D7) -> 1 | M7: =YEAR(D7) -> 2026 | N7: =D7*1 -> 46023 | O7: =F7/E7 -> 0.1093 | P7: =O7*E7 -> 10.93 | Q7: =G7/E7 -> 0.0499 | R7: =O7+Q7 -> 0.1592 | S7: =R7*E7 -> 15.92 | T7: =-(F7-H7)/E7 -> -0.0186 | U7: =R7+T7 -> 0.1406 | V7: =U7*E7 -> 14.06 | W7: =SUMIF(GLS!B:B,K7,GLS!C:C) -> 5.25 | Z7: =-IF(W7+X7+Y7=0,"à vérifier",W7+X7+Y7) -> -5.25 | AA7: =IFERROR((SUMIF($K:$K,K7,$Z:$Z)/COUNTIF($K:$K,K7))*E7/SUMIF($K:$K,K7,$E:$E),0) -> -5.25 | AB7: =AA7/E7 -> -0.0525 | AC7: =AB7+U7 -> 0.0881 | AD7: =AC7/R7 -> 0.55339196 | AE7: =AC7*E7 -> 8.81 | AF7: =IFERROR(-ABS(INDEX('frais amazon 011225-150326'!H:H,MATCH(Reproting_ERPALIN!K7,'frais amazon 011225-150326'!D:D,0))/1.2),"Commande hors la France") -> -2.9666667 | AG7: =IFERROR(AF7*E7/SUMIF($K:$K,K7,$E:$E),0) -> -2.9666667 | AH7: =AG7/E7 -> -0.029666667 | AI7: =AH7+AC7 -> 0.058433333 | AJ7: =AI7/R7 -> 0.36704355 | AK7: =AI7*E7 -> 5.8433333
A8: Abena - Couches adulte intraversables Maternity Pad Super - Sachet de 15 pièces | B8: 1000022654 | C8: Abena | D8: 2026-02-01 | E8: 30 | F8: 14.35 | G8: 0 | H8: 10.08 | I8: 70.21 | J8: FR | K8: 408-9658495-7513141 | L8: =MONTH(D8) -> 2 | M8: =YEAR(D8) -> 2026 | N8: =D8*1 -> 46054 | O8: =F8/E8 -> 0.47833333 | P8: =O8*E8 -> 14.35 | Q8: =G8/E8 -> 0 | R8: =O8+Q8 -> 0.47833333 | S8: =R8*E8 -> 14.35 | T8: =-(F8-H8)/E8 -> -0.14233333 | U8: =R8+T8 -> 0.336 | V8: =U8*E8 -> 10.08 | W8: =SUMIF(GLS!B:B,K8,GLS!C:C) -> 5.25 | Z8: =-IF(W8+X8+Y8=0,"à vérifier",W8+X8+Y8) -> -5.25 | AA8: =IFERROR((SUMIF($K:$K,K8,$Z:$Z)/COUNTIF($K:$K,K8))*E8/SUMIF($K:$K,K8,$E:$E),0) -> -5.25 | AB8: =AA8/E8 -> -0.175 | AC8: =AB8+U8 -> 0.161 | AD8: =AC8/R8 -> 0.33658537 | AE8: =AC8*E8 -> 4.83 | AF8: =IFERROR(-ABS(INDEX('frais amazon 011225-150326'!H:H,MATCH(Reproting_ERPALIN!K8,'frais amazon 011225-150326'!D:D,0))/1.2),"Commande hors la France") -> -2.6666667 | AG8: =IFERROR(AF8*E8/SUMIF($K:$K,K8,$E:$E),0) -> -2.6666667 | AH8: =AG8/E8 -> -0.088888889 | AI8: =AH8+AC8 -> 0.072111111 | AJ8: =AI8/R8 -> 0.15075494 | AK8: =AI8*E8 -> 2.1633333
A9: HARTMANN - ZETUVIT E Pansement absorbant stérile 15 x 20 cm (413792) - Boite de 25 pièces | B9: 413772 | C9: Hartmann | D9: 2026-02-01 | E9: 25 | F9: 9.17 | G9: 8.73 | H9: 3.9 | I9: 42.5 | J9: ES | K9: 408-9628751-6035569 | L9: =MONTH(D9) -> 2 | M9: =YEAR(D9) -> 2026 | N9: =D9*1 -> 46054 | O9: =F9/E9 -> 0.3668 | P9: =O9*E9 -> 9.17 | Q9: =G9/E9 -> 0.3492 | R9: =O9+Q9 -> 0.716 | S9: =R9*E9 -> 17.9 | T9: =-(F9-H9)/E9 -> -0.2108 | U9: =R9+T9 -> 0.5052 | V9: =U9*E9 -> 12.63 | W9: =SUMIF(GLS!B:B,K9,GLS!C:C) -> 10.72 | Z9: =-IF(W9+X9+Y9=0,"à vérifier",W9+X9+Y9) -> -10.72 | AA9: =IFERROR((SUMIF($K:$K,K9,$Z:$Z)/COUNTIF($K:$K,K9))*E9/SUMIF($K:$K,K9,$E:$E),0) -> -10.72 | AB9: =AA9/E9 -> -0.4288 | AC9: =AB9+U9 -> 0.0764 | AD9: =AC9/R9 -> 0.10670391 | AE9: =AC9*E9 -> 1.91 | AF9: =IFERROR(-ABS(INDEX('frais amazon 011225-150326'!H:H,MATCH(Reproting_ERPALIN!K9,'frais amazon 011225-150326'!D:D,0))/1.2),"Commande hors la France") -> Commande hors la France | AG9: =IFERROR(AF9*E9/SUMIF($K:$K,K9,$E:$E),0) -> 0 | AH9: =AG9/E9 -> 0 | AI9: =AH9+AC9 -> 0.0764 | AJ9: =AI9/R9 -> 0.10670391 | AK9: =AI9*E9 -> 1.91
A10: Compresse non tissé stérile 40 g/m2 , 10 cm x 10cm | B10: NL105-S-40 | C10: ZARYS International Group sp. z o.o. sp.k. | D10: 2026-02-01 | E10: 200 | F10: 24.4 | G10: 10.64 | H10: 22.04 | I10: 90.33 | J10: IT | K10: 408-9280083-9908352 | L10: =MONTH(D10) -> 2 | M10: =YEAR(D10) -> 2026 | N10: =D10*1 -> 46054 | O10: =F10/E10 -> 0.122 | P10: =O10*E10 -> 24.4 | Q10: =G10/E10 -> 0.0532 | R10: =O10+Q10 -> 0.1752 | S10: =R10*E10 -> 35.04 | T10: =-(F10-H10)/E10 -> -0.0118 | U10: =R10+T10 -> 0.1634 | V10: =U10*E10 -> 32.68 | W10: =SUMIF(GLS!B:B,K10,GLS!C:C) -> 10.72 | Z10: =-IF(W10+X10+Y10=0,"à vérifier",W10+X10+Y10) -> -10.72 | AA10: =IFERROR((SUMIF($K:$K,K10,$Z:$Z)/COUNTIF($K:$K,K10))*E10/SUMIF($K:$K,K10,$E:$E),0) -> -10.72 | AB10: =AA10/E10 -> -0.0536 | AC10: =AB10+U10 -> 0.1098 | AD10: =AC10/R10 -> 0.62671233 | AE10: =AC10*E10 -> 21.96 | AF10: =IFERROR(-ABS(INDEX('frais amazon 011225-150326'!H:H,MATCH(Reproting_ERPALIN!K10,'frais amazon 011225-150326'!D:D,0))/1.2),"Commande hors la France") -> Commande hors la France | AG10: =IFERROR(AF10*E10/SUMIF($K:$K,K10,$E:$E),0) -> 0 | AH10: =AG10/E10 -> 0 | AI10: =AH10+AC10 -> 0.1098 | AJ10: =AI10/R10 -> 0.62671233 | AK10: =AI10*E10 -> 21.96
A11: Aiguille hypodermique à usage unique non sécurisée 25G, 0,5 mm x 40 mm | B11: IN-05X40 | C11: ZARYS International Group sp. z o.o. sp.k. | D11: 2026-01-01 | E11: 100 | F11: 10.72 | G11: 4.99 | H11: 9.85 | I11: 91.88 | J11: FR | K11: 408-8992526-7392325 | L11: =MONTH(D11) -> 1 | M11: =YEAR(D11) -> 2026 | N11: =D11*1 -> 46023 | O11: =F11/E11 -> 0.1072 | P11: =O11*E11 -> 10.72 | Q11: =G11/E11 -> 0.0499 | R11: =O11+Q11 -> 0.1571 | S11: =R11*E11 -> 15.71 | T11: =-(F11-H11)/E11 -> -0.0087 | U11: =R11+T11 -> 0.1484 | V11: =U11*E11 -> 14.84 | W11: =SUMIF(GLS!B:B,K11,GLS!C:C) -> 9.59 | Z11: =-IF(W11+X11+Y11=0,"à vérifier",W11+X11+Y11) -> -9.59 | AA11: =IFERROR((SUMIF($K:$K,K11,$Z:$Z)/COUNTIF($K:$K,K11))*E11/SUMIF($K:$K,K11,$E:$E),0) -> -9.59 | AB11: =AA11/E11 -> -0.0959 | AC11: =AB11+U11 -> 0.0525 | AD11: =AC11/R11 -> 0.33418205 | AE11: =AC11*E11 -> 5.25 | AF11: =IFERROR(-ABS(INDEX('frais amazon 011225-150326'!H:H,MATCH(Reproting_ERPALIN!K11,'frais amazon 011225-150326'!D:D,0))/1.2),"Commande hors la France") -> -2.9 | AG11: =IFERROR(AF11*E11/SUMIF($K:$K,K11,$E:$E),0) -> -2.9 | AH11: =AG11/E11 -> -0.029 | AI11: =AH11+AC11 -> 0.0235 | AJ11: =AI11/R11 -> 0.14958625 | AK11: =AI11*E11 -> 2.35
A12: HARTMANN Lastopress Bande de Gaze Chair 7 cm x 3 m | B12: 931305 | C12: Hartmann | D12: 2026-01-01 | E12: 2 | F12: 13.72 | G12: 4.99 | H12: -0.46 | I12: -3.37 | J12: FR | K12: 408-8986799-6135540 | L12: =MONTH(D12) -> 1 | M12: =YEAR(D12) -> 2026 | N12: =D12*1 -> 46023 | O12: =F12/E12 -> 6.86 | P12: =O12*E12 -> 13.72 | Q12: =G12/E12 -> 2.495 | R12: =O12+Q12 -> 9.355 | S12: =R12*E12 -> 18.71 | T12: =-(F12-H12)/E12 -> -7.09 | U12: =R12+T12 -> 2.265 | V12: =U12*E12 -> 4.53 | W12: =SUMIF(GLS!B:B,K12,GLS!C:C) -> 5.25 | Z12: =-IF(W12+X12+Y12=0,"à vérifier",W12+X12+Y12) -> -5.25 | AA12: =IFERROR((SUMIF($K:$K,K12,$Z:$Z)/COUNTIF($K:$K,K12))*E12/SUMIF($K:$K,K12,$E:$E),0) -> -5.25 | AB12: =AA12/E12 -> -2.625 | AC12: =AB12+U12 -> -0.36 | AD12: =AC12/R12 -> -0.038482095 | AE12: =AC12*E12 -> -0.72 | AF12: =IFERROR(-ABS(INDEX('frais amazon 011225-150326'!H:H,MATCH(Reproting_ERPALIN!K12,'frais amazon 011225-150326'!D:D,0))/1.2),"Commande hors la France") -> -3.4666667 | AG12: =IFERROR(AF12*E12/SUMIF($K:$K,K12,$E:$E),0) -> -3.4666667 | AH12: =AG12/E12 -> -1.7333333 | AI12: =AH12+AC12 -> -2.0933333 | AJ12: =AI12/R12 -> -0.22376626 | AK12: =AI12*E12 -> -4.1866667
A13: Carrés de soin 50g Octolin 30 x 40 cm - Sachet de 50 pièces | B13: 684358 | C13: Hartmann | D13: 2026-01-01 | E13: 50 | F13: 6.09 | G13: 2.495 | H13: 4.51 | I13: 74.06 | J13: FR | K13: 408-8986137-3153951 | L13: =MONTH(D13) -> 1 | M13: =YEAR(D13) -> 2026 | N13: =D13*1 -> 46023 | O13: =F13/E13 -> 0.1218 | P13: =O13*E13 -> 6.09 | Q13: =G13/E13 -> 0.0499 | R13: =O13+Q13 -> 0.1717 | S13: =R13*E13 -> 8.585 | T13: =-(F13-H13)/E13 -> -0.0316 | U13: =R13+T13 -> 0.1401 | V13: =U13*E13 -> 7.005 | W13: =SUMIF(GLS!B:B,K13,GLS!C:C) -> 5.25 | Z13: =-IF(W13+X13+Y13=0,"à vérifier",W13+X13+Y13) -> -5.25 | AA13: =IFERROR((SUMIF($K:$K,K13,$Z:$Z)/COUNTIF($K:$K,K13))*E13/SUMIF($K:$K,K13,$E:$E),0) -> -2.625 | AB13: =AA13/E13 -> -0.0525 | AC13: =AB13+U13 -> 0.0876 | AD13: =AC13/R13 -> 0.5101922 | AE13: =AC13*E13 -> 4.38 | AF13: =IFERROR(-ABS(INDEX('frais amazon 011225-150326'!H:H,MATCH(Reproting_ERPALIN!K13,'frais amazon 011225-150326'!D:D,0))/1.2),"Commande hors la France") -> -2.2083333 | AG13: =IFERROR(AF13*E13/SUMIF($K:$K,K13,$E:$E),0) -> -1.1041667 | AH13: =AG13/E13 -> -0.022083333 | AI13: =AH13+AC13 -> 0.065516667 | AJ13: =AI13/R13 -> 0.38157639 | AK13: =AI13*E13 -> 3.2758333
A14: HARTMANN - Carrés de soin 50g Octolin 29 x 33 cm - Sachet de 50 pièces | B14: 684352 | C14: Hartmann | D14: 2026-01-01 | E14: 50 | F14: 5.87 | G14: 2.495 | H14: 4.52 | I14: 77 | J14: FR | K14: 408-8986137-3153951 | L14: =MONTH(D14) -> 1 | M14: =YEAR(D14) -> 2026 | N14: =D14*1 -> 46023 | O14: =F14/E14 -> 0.1174 | P14: =O14*E14 -> 5.87 | Q14: =G14/E14 -> 0.0499 | R14: =O14+Q14 -> 0.1673 | S14: =R14*E14 -> 8.365 | T14: =-(F14-H14)/E14 -> -0.027 | U14: =R14+T14 -> 0.1403 | V14: =U14*E14 -> 7.015 | W14: =SUMIF(GLS!B:B,K14,GLS!C:C) -> 5.25 | Z14: =-IF(W14+X14+Y14=0,"à vérifier",W14+X14+Y14) -> -5.25 | AA14: =IFERROR((SUMIF($K:$K,K14,$Z:$Z)/COUNTIF($K:$K,K14))*E14/SUMIF($K:$K,K14,$E:$E),0) -> -2.625 | AB14: =AA14/E14 -> -0.0525 | AC14: =AB14+U14 -> 0.0878 | AD14: =AC14/R14 -> 0.52480574 | AE14: =AC14*E14 -> 4.39 | AF14: =IFERROR(-ABS(INDEX('frais amazon 011225-150326'!H:H,MATCH(Reproting_ERPALIN!K14,'frais amazon 011225-150326'!D:D,0))/1.2),"Commande hors la France") -> -2.2083333 | AG14: =IFERROR(AF14*E14/SUMIF($K:$K,K14,$E:$E),0) -> -1.1041667 | AH14: =AG14/E14 -> -0.022083333 | AI14: =AH14+AC14 -> 0.065716667 | AJ14: =AI14/R14 -> 0.39280733 | AK14: =AI14*E14 -> 3.2858333
A15: Aiguille hypodermique à usage unique non sécurisée 20G, 0,9 mm x 25 mm | B15: IN-09X25 | C15: ZARYS International Group sp. z o.o. sp.k. | D15: 2026-02-01 | E15: 100 | F15: 10.32 | G15: 4.99 | H15: 9.56 | I15: 92.64 | J15: FR | K15: 408-8973722-1049161 | L15: =MONTH(D15) -> 2 | M15: =YEAR(D15) -> 2026 | N15: =D15*1 -> 46054 | O15: =F15/E15 -> 0.1032 | P15: =O15*E15 -> 10.32 | Q15: =G15/E15 -> 0.0499 | R15: =O15+Q15 -> 0.1531 | S15: =R15*E15 -> 15.31 | T15: =-(F15-H15)/E15 -> -0.0076 | U15: =R15+T15 -> 0.1455 | V15: =U15*E15 -> 14.55 | W15: =SUMIF(GLS!B:B,K15,GLS!C:C) -> 5.25 | Z15: =-IF(W15+X15+Y15=0,"à vérifier",W15+X15+Y15) -> -5.25 | AA15: =IFERROR((SUMIF($K:$K,K15,$Z:$Z)/COUNTIF($K:$K,K15))*E15/SUMIF($K:$K,K15,$E:$E),0) -> -5.25 | AB15: =AA15/E15 -> -0.0525 | AC15: =AB15+U15 -> 0.093 | AD15: =AC15/R15 -> 0.60744611 | AE15: =AC15*E15 -> 9.3 | AF15: =IFERROR(-ABS(INDEX('frais amazon 011225-150326'!H:H,MATCH(Reproting_ERPALIN!K15,'frais amazon 011225-150326'!D:D,0))/1.2),"Commande hors la France") -> -2.8333333 | AG15: =IFERROR(AF15*E15/SUMIF($K:$K,K15,$E:$E),0) -> -2.8333333 | AH15: =AG15/E15 -> -0.028333333 | AI15: =AH15+AC15 -> 0.064666667 | AJ15: =AI15/R15 -> 0.42238189 | AK15: =AI15*E15 -> 6.4666667
A16: Abena - Couches adulte intraversables Maternity Pad Super - Sachet de 15 pièces | B16: 1000022654 | C16: Abena | D16: 2026-01-01 | E16: 30 | F16: 14.35 | G16: 0 | H16: 10.08 | I16: 70.21 | J16: FR | K16: 408-8949959-8811522 | L16: =MONTH(D16) -> 1 | M16: =YEAR(D16) -> 2026 | N16: =D16*1 -> 46023 | O16: =F16/E16 -> 0.47833333 | P16: =O16*E16 -> 14.35 | Q16: =G16/E16 -> 0 | R16: =O16+Q16 -> 0.47833333 | S16: =R16*E16 -> 14.35 | T16: =-(F16-H16)/E16 -> -0.14233333 | U16: =R16+T16 -> 0.336 | V16: =U16*E16 -> 10.08 | W16: =SUMIF(GLS!B:B,K16,GLS!C:C) -> 5.48 | Z16: =-IF(W16+X16+Y16=0,"à vérifier",W16+X16+Y16) -> -5.48 | AA16: =IFERROR((SUMIF($K:$K,K16,$Z:$Z)/COUNTIF($K:$K,K16))*E16/SUMIF($K:$K,K16,$E:$E),0) -> -5.48 | AB16: =AA16/E16 -> -0.18266667 | AC16: =AB16+U16 -> 0.15333333 | AD16: =AC16/R16 -> 0.32055749 | AE16: =AC16*E16 -> 4.6 | AF16: =IFERROR(-ABS(INDEX('frais amazon 011225-150326'!H:H,MATCH(Reproting_ERPALIN!K16,'frais amazon 011225-150326'!D:D,0))/1.2),"Commande hors la France") -> -2.6666667 | AG16: =IFERROR(AF16*E16/SUMIF($K:$K,K16,$E:$E),0) -> -2.6666667 | AH16: =AG16/E16 -> -0.088888889 | AI16: =AH16+AC16 -> 0.064444444 | AJ16: =AI16/R16 -> 0.13472706 | AK16: =AI16*E16 -> 1.9333333
A17: Aiguille hypodermique à usage unique non sécurisée 25G, 0,5 mm x 40 mm | B17: IN-05X40 | C17: ZARYS International Group sp. z o.o. sp.k. | D17: 2026-01-01 | E17: 100 | F17: 10.04 | G17: 4.99 | H17: 9.17 | I17: 91.33 | J17: FR | K17: 408-8842324-5805908 | L17: =MONTH(D17) -> 1 | M17: =YEAR(D17) -> 2026 | N17: =D17*1 -> 46023 | O17: =F17/E17 -> 0.1004 | P17: =O17*E17 -> 10.04 | Q17: =G17/E17 -> 0.0499 | R17: =O17+Q17 -> 0.1503 | S17: =R17*E17 -> 15.03 | T17: =-(F17-H17)/E17 -> -0.0087 | U17: =R17+T17 -> 0.1416 | V17: =U17*E17 -> 14.16 | W17: =SUMIF(GLS!B:B,K17,GLS!C:C) -> 5.25 | Z17: =-IF(W17+X17+Y17=0,"à vérifier",W17+X17+Y17) -> -5.25 | AA17: =IFERROR((SUMIF($K:$K,K17,$Z:$Z)/COUNTIF($K:$K,K17))*E17/SUMIF($K:$K,K17,$E:$E),0) -> -5.25 | AB17: =AA17/E17 -> -0.0525 | AC17: =AB17+U17 -> 0.0891 | AD17: =AC17/R17 -> 0.59281437 | AE17: =AC17*E17 -> 8.91 | AF17: =IFERROR(-ABS(INDEX('frais amazon 011225-150326'!H:H,MATCH(Reproting_ERPALIN!K17,'frais amazon 011225-150326'!D:D,0))/1.2),"Commande hors la France") -> -2.7833333 | AG17: =IFERROR(AF17*E17/SUMIF($K:$K,K17,$E:$E),0) -> -2.7833333 | AH17: =AG17/E17 -> -0.027833333 | AI17: =AH17+AC17 -> 0.061266667 | AJ17: =AI17/R17 -> 0.40762919 | AK17: =AI17*E17 -> 6.1266667
A18: HARTMANN - ZETUVIT E Pansement absorbant stérile 15 x 20 cm (413792) - Boite de 25 pièces | B18: 413772 | C18: Hartmann | D18: 2026-01-01 | E18: 100 | F18: 36.97 | G18: 11.45 | H18: 15.88 | I18: 42.95 | J18: IT | K18: 408-8834949-5530704 | L18: =MONTH(D18) -> 1 | M18: =YEAR(D18) -> 2026 | N18: =D18*1 -> 46023 | O18: =F18/E18 -> 0.3697 | P18: =O18*E18 -> 36.97 | Q18: =G18/E18 -> 0.1145 | R18: =O18+Q18 -> 0.4842 | S18: =R18*E18 -> 48.42 | T18: =-(F18-H18)/E18 -> -0.2109 | U18: =R18+T18 -> 0.2733 | V18: =U18*E18 -> 27.33 | W18: =SUMIF(GLS!B:B,K18,GLS!C:C) -> 10.72 | Z18: =-IF(W18+X18+Y18=0,"à vérifier",W18+X18+Y18) -> -10.72 | AA18: =IFERROR((SUMIF($K:$K,K18,$Z:$Z)/COUNTIF($K:$K,K18))*E18/SUMIF($K:$K,K18,$E:$E),0) -> -10.72 | AB18: =AA18/E18 -> -0.1072 | AC18: =AB18+U18 -> 0.1661 | AD18: =AC18/R18 -> 0.34304007 | AE18: =AC18*E18 -> 16.61 | AF18: =IFERROR(-ABS(INDEX('frais amazon 011225-150326'!H:H,MATCH(Reproting_ERPALIN!K18,'frais amazon 011225-150326'!D:D,0))/1.2),"Commande hors la France") -> Commande hors la France | AG18: =IFERROR(AF18*E18/SUMIF($K:$K,K18,$E:$E),0) -> 0 | AH18: =AG18/E18 -> 0 | AI18: =AH18+AC18 -> 0.1661 | AJ18: =AI18/R18 -> 0.34304007 | AK18: =AI18*E18 -> 16.61
A19: AIGUILLE HYPODERMIQUE 21G 25MM | B19: IN-08X25 | C19: ZARYS International Group sp. z o.o. sp.k. | D19: 2026-01-01 | E19: 200 | F19: 19.12 | G19: 4.99 | H19: 17.7 | I19: 92.57 | J19: FR | K19: 408-8808819-1426760 | L19: =MONTH(D19) -> 1 | M19: =YEAR(D19) -> 2026 | N19: =D19*1 -> 46023 | O19: =F19/E19 -> 0.0956 | P19: =O19*E19 -> 19.12 | Q19: =G19/E19 -> 0.02495 | R19: =O19+Q19 -> 0.12055 | S19: =R19*E19 -> 24.11 | T19: =-(F19-H19)/E19 -> -0.0071 | U19: =R19+T19 -> 0.11345 | V19: =U19*E19 -> 22.69 | W19: =SUMIF(GLS!B:B,K19,GLS!C:C) -> 5.25 | Z19: =-IF(W19+X19+Y19=0,"à vérifier",W19+X19+Y19) -> -5.25 | AA19: =IFERROR((SUMIF($K:$K,K19,$Z:$Z)/COUNTIF($K:$K,K19))*E19/SUMIF($K:$K,K19,$E:$E),0) -> -5.25 | AB19: =AA19/E19 -> -0.02625 | AC19: =AB19+U19 -> 0.0872 | AD19: =AC19/R19 -> 0.72335131 | AE19: =AC19*E19 -> 17.44 | AF19: =IFERROR(-ABS(INDEX('frais amazon 011225-150326'!H:H,MATCH(Reproting_ERPALIN!K19,'frais amazon 011225-150326'!D:D,0))/1.2),"Commande hors la France") -> -4.4583333 | AG19: =IFERROR(AF19*E19/SUMIF($K:$K,K19,$E:$E),0) -> -4.4583333 | AH19: =AG19/E19 -> -0.022291667 | AI19: =AH19+AC19 -> 0.064908333 | AJ19: =AI19/R19 -> 0.53843495 | AK19: =AI19*E19 -> 12.981667
A20: Aiguille hypodermique à usage unique non sécurisée 21G, 0,8 mm x 50 mm | B20: IN-08X50 | C20: ZARYS International Group sp. z o.o. sp.k. | D20: 2026-01-01 | E20: 100 | F20: 12.98 | G20: 4.99 | H20: 11.52 | I20: 88.75 | J20: FR | K20: 408-8763175-7451554 | L20: =MONTH(D20) -> 1 | M20: =YEAR(D20) -> 2026 | N20: =D20*1 -> 46023 | O20: =F20/E20 -> 0.1298 | P20: =O20*E20 -> 12.98 | Q20: =G20/E20 -> 0.0499 | R20: =O20+Q20 -> 0.1797 | S20: =R20*E20 -> 17.97 | T20: =-(F20-H20)/E20 -> -0.0146 | U20: =R20+T20 -> 0.1651 | V20: =U20*E20 -> 16.51 | W20: =SUMIF(GLS!B:B,K20,GLS!C:C) -> 5.25 | Z20: =-IF(W20+X20+Y20=0,"à vérifier",W20+X20+Y20) -> -5.25 | AA20: =IFERROR((SUMIF($K:$K,K20,$Z:$Z)/COUNTIF($K:$K,K20))*E20/SUMIF($K:$K,K20,$E:$E),0) -> -5.25 | AB20: =AA20/E20 -> -0.0525 | AC20: =AB20+U20 -> 0.1126 | AD20: =AC20/R20 -> 0.62659989 | AE20: =AC20*E20 -> 11.26 | AF20: =IFERROR(-ABS(INDEX('frais amazon 011225-150326'!H:H,MATCH(Reproting_ERPALIN!K20,'frais amazon 011225-150326'!D:D,0))/1.2),"Commande hors la France") -> -3.3333333 | AG20: =IFERROR(AF20*E20/SUMIF($K:$K,K20,$E:$E),0) -> -3.3333333 | AH20: =AG20/E20 -> -0.033333333 | AI20: =AH20+AC20 -> 0.079266667 | AJ20: =AI20/R20 -> 0.44110555 | AK20: =AI20*E20 -> 7.9266667
A21: Abena - Couches adulte intraversables Maternity Pad Super - Sachet de 15 pièces | B21: 1000022654 | C21: Abena | D21: 2026-02-01 | E21: 30 | F21: 13.49 | G21: 0 | H21: 9.22 | I21: 68.31 | J21: FR | K21: 408-8732277-5985169 | L21: =MONTH(D21) -> 2 | M21: =YEAR(D21) -> 2026 | N21: =D21*1 -> 46054 | O21: =F21/E21 -> 0.44966667 | P21: =O21*E21 -> 13.49 | Q21: =G21/E21 -> 0 | R21: =O21+Q21 -> 0.44966667 | S21: =R21*E21 -> 13.49 | T21: =-(F21-H21)/E21 -> -0.14233333 | U21: =R21+T21 -> 0.30733333 | V21: =U21*E21 -> 9.22 | W21: =SUMIF(GLS!B:B,K21,GLS!C:C) -> 5.25 | Z21: =-IF(W21+X21+Y21=0,"à vérifier",W21+X21+Y21) -> -5.25 | AA21: =IFERROR((SUMIF($K:$K,K21,$Z:$Z)/COUNTIF($K:$K,K21))*E21/SUMIF($K:$K,K21,$E:$E),0) -> -5.25 | AB21: =AA21/E21 -> -0.175 | AC21: =AB21+U21 -> 0.13233333 | AD21: =AC21/R21 -> 0.29429207 | AE21: =AC21*E21 -> 3.97 | AF21: =IFERROR(-ABS(INDEX('frais amazon 011225-150326'!H:H,MATCH(Reproting_ERPALIN!K21,'frais amazon 011225-150326'!D:D,0))/1.2),"Commande hors la France") -> -2.5083333 | AG21: =IFERROR(AF21*E21/SUMIF($K:$K,K21,$E:$E),0) -> -2.5083333 | AH21: =AG21/E21 -> -0.083611111 | AI21: =AH21+AC21 -> 0.048722222 | AJ21: =AI21/R21 -> 0.10835187 | AK21: =AI21*E21 -> 1.4616667
A22: Carrés de soin 50g Octolin 30 x 40 cm - Sachet de 50 pièces | B22: 684358 | C22: Hartmann | D22: 2026-01-01 | E22: 50 | F22: 5.77 | G22: 0.71285714 | H22: 4.19 | I22: 72.62 | J22: FR | K22: 408-8712382-7341952 | L22: =MONTH(D22) -> 1 | M22: =YEAR(D22) -> 2026 | N22: =D22*1 -> 46023 | O22: =F22/E22 -> 0.1154 | P22: =O22*E22 -> 5.77 | Q22: =G22/E22 -> 0.014257143 | R22: =O22+Q22 -> 0.12965714 | S22: =R22*E22 -> 6.4828571 | T22: =-(F22-H22)/E22 -> -0.0316 | U22: =R22+T22 -> 0.098057143 | V22: =U22*E22 -> 4.9028571 | W22: =SUMIF(GLS!B:B,K22,GLS!C:C) -> 5.49 | Z22: =-IF(W22+X22+Y22=0,"à vérifier",W22+X22+Y22) -> -5.49 | AA22: =IFERROR((SUMIF($K:$K,K22,$Z:$Z)/COUNTIF($K:$K,K22))*E22/SUMIF($K:$K,K22,$E:$E),0) -> -0.78428571 | AB22: =AA22/E22 -> -0.015685714 | AC22: =AB22+U22 -> 0.082371429 | AD22: =AC22/R22 -> 0.6353019 | AE22: =AC22*E22 -> 4.1185714 | AF22: =IFERROR(-ABS(INDEX('frais amazon 011225-150326'!H:H,MATCH(Reproting_ERPALIN!K22,'frais amazon 011225-150326'!D:D,0))/1.2),"Commande hors la France") -> -6.7916667 | AG22: =IFERROR(AF22*E22/SUMIF($K:$K,K22,$E:$E),0) -> -0.9702381 | AH22: =AG22/E22 -> -0.019404762 | AI22: =AH22+AC22 -> 0.062966667 | AJ22: =AI22/R22 -> 0.48563978 | AK22: =AI22*E22 -> 3.1483333
A23: HARTMANN - Carrés de soin 50g Octolin 29 x 33 cm - Sachet de 50 pièces | B23: 684352 | C23: Hartmann | D23: 2026-01-01 | E23: 300 | F23: 35.19 | G23: 4.2771429 | H23: 27.09 | I23: 76.98 | J23: FR | K23: 408-8712382-7341952 | L23: =MONTH(D23) -> 1 | M23: =YEAR(D23) -> 2026 | N23: =D23*1 -> 46023 | O23: =F23/E23 -> 0.1173 | P23: =O23*E23 -> 35.19 | Q23: =G23/E23 -> 0.014257143 | R23: =O23+Q23 -> 0.13155714 | S23: =R23*E23 -> 39.467143 | T23: =-(F23-H23)/E23 -> -0.027 | U23: =R23+T23 -> 0.10455714 | V23: =U23*E23 -> 31.367143 | W23: =SUMIF(GLS!B:B,K23,GLS!C:C) -> 5.49 | Z23: =-IF(W23+X23+Y23=0,"à vérifier",W23+X23+Y23) -> -5.49 | AA23: =IFERROR((SUMIF($K:$K,K23,$Z:$Z)/COUNTIF($K:$K,K23))*E23/SUMIF($K:$K,K23,$E:$E),0) -> -4.7057143 | AB23: =AA23/E23 -> -0.015685714 | AC23: =AB23+U23 -> 0.088871429 | AD23: =AC23/R23 -> 0.6755348 | AE23: =AC23*E23 -> 26.661429 | AF23: =IFERROR(-ABS(INDEX('frais amazon 011225-150326'!H:H,MATCH(Reproting_ERPALIN!K23,'frais amazon 011225-150326'!D:D,0))/1.2),"Commande hors la France") -> -6.7916667 | AG23: =IFERROR(AF23*E23/SUMIF($K:$K,K23,$E:$E),0) -> -5.8214286 | AH23: =AG23/E23 -> -0.019404762 | AI23: =AH23+AC23 -> 0.069466667 | AJ23: =AI23/R23 -> 0.52803417 | AK23: =AI23*E23 -> 20.84
A24: Alèse jetable de protection Extra soft pour chaises et lits 60 x 60 cm | B24: 254125 | C24: Abena | D24: 2026-01-01 | E24: 10 | F24: 6.64 | G24: 10.83 | H24: 3.16 | I24: 47.64 | J24: IT | K24: 408-8615211-9073139 | L24: =MONTH(D24) -> 1 | M24: =YEAR(D24) -> 2026 | N24: =D24*1 -> 46023 | O24: =F24/E24 -> 0.664 | P24: =O24*E24 -> 6.64 | Q24: =G24/E24 -> 1.083 | R24: =O24+Q24 -> 1.747 | S24: =R24*E24 -> 17.47 | T24: =-(F24-H24)/E24 -> -0.348 | U24: =R24+T24 -> 1.399 | V24: =U24*E24 -> 13.99 | W24: =SUMIF(GLS!B:B,K24,GLS!C:C) -> 11.05 | Z24: =-IF(W24+X24+Y24=0,"à vérifier",W24+X24+Y24) -> -11.05 | AA24: =IFERROR((SUMIF($K:$K,K24,$Z:$Z)/COUNTIF($K:$K,K24))*E24/SUMIF($K:$K,K24,$E:$E),0) -> -11.05 | AB24: =AA24/E24 -> -1.105 | AC24: =AB24+U24 -> 0.294 | AD24: =AC24/R24 -> 0.16828849 | AE24: =AC24*E24 -> 2.94 | AF24: =IFERROR(-ABS(INDEX('frais amazon 011225-150326'!H:H,MATCH(Reproting_ERPALIN!K24,'frais amazon 011225-150326'!D:D,0))/1.2),"Commande hors la France") -> Commande hors la France | AG24: =IFERROR(AF24*E24/SUMIF($K:$K,K24,$E:$E),0) -> 0 | AH24: =AG24/E24 -> 0 | AI24: =AH24+AC24 -> 0.294 | AJ24: =AI24/R24 -> 0.16828849 | AK24: =AI24*E24 -> 2.94
A25: Seringue à insuline, stérile - Boite de 100 pièces - Rouge | B25: IN-U40-1-BL | C25: ZARYS International Group sp. z o.o. sp.k. | D25: 2026-01-01 | E25: 100 | F25: 16.87 | G25: 16.31 | H25: 14.76 | I25: 87.49 | J25: IT | K25: 408-8512935-6400369 | L25: =MONTH(D25) -> 1 | M25: =YEAR(D25) -> 2026 | N25: =D25*1 -> 46023 | O25: =F25/E25 -> 0.1687 | P25: =O25*E25 -> 16.87 | Q25: =G25/E25 -> 0.1631 | R25: =O25+Q25 -> 0.3318 | S25: =R25*E25 -> 33.18 | T25: =-(F25-H25)/E25 -> -0.0211 | U25: =R25+T25 -> 0.3107 | V25: =U25*E25 -> 31.07 | W25: =SUMIF(GLS!B:B,K25,GLS!C:C) -> 10.72 | Z25: =-IF(W25+X25+Y25=0,"à vérifier",W25+X25+Y25) -> -10.72 | AA25: =IFERROR((SUMIF($K:$K,K25,$Z:$Z)/COUNTIF($K:$K,K25))*E25/SUMIF($K:$K,K25,$E:$E),0) -> -10.72 | AB25: =AA25/E25 -> -0.1072 | AC25: =AB25+U25 -> 0.2035 | AD25: =AC25/R25 -> 0.61332128 | AE25: =AC25*E25 -> 20.35 | AF25: =IFERROR(-ABS(INDEX('frais amazon 011225-150326'!H:H,MATCH(Reproting_ERPALIN!K25,'frais amazon 011225-150326'!D:D,0))/1.2),"Commande hors la France") -> Commande hors la France | AG25: =IFERROR(AF25*E25/SUMIF($K:$K,K25,$E:$E),0) -> 0 | AH25: =AG25/E25 -> 0 | AI25: =AH25+AC25 -> 0.2035 | AJ25: =AI25/R25 -> 0.61332128 | AK25: =AI25*E25 -> 20.35
A26: FL MEDICAL - Pots à urine 120 ml avec étiquette avec bouchon à vis - 300 pièces | B26: 25033 | C26: FL MEDICAL | D26: 2026-01-01 | E26: 300 | F26: 32.52 | G26: 12.26 | H26: 16.17 | I26: 49.72 | J26: IT | K26: 408-8462591-7611546 | L26: =MONTH(D26) -> 1 | M26: =YEAR(D26) -> 2026 | N26: =D26*1 -> 46023 | O26: =F26/E26 -> 0.1084 | P26: =O26*E26 -> 32.52 | Q26: =G26/E26 -> 0.040866667 | R26: =O26+Q26 -> 0.14926667 | S26: =R26*E26 -> 44.78 | T26: =-(F26-H26)/E26 -> -0.0545 | U26: =R26+T26 -> 0.094766667 | V26: =U26*E26 -> 28.43 | W26: =SUMIF(GLS!B:B,K26,GLS!C:C) -> 66.84 | Z26: =-IF(W26+X26+Y26=0,"à vérifier",W26+X26+Y26) -> -66.84 | AA26: =IFERROR((SUMIF($K:$K,K26,$Z:$Z)/COUNTIF($K:$K,K26))*E26/SUMIF($K:$K,K26,$E:$E),0) -> -66.84 | AB26: =AA26/E26 -> -0.2228 | AC26: =AB26+U26 -> -0.12803333 | AD26: =AC26/R26 -> -0.857749 | AE26: =AC26*E26 -> -38.41 | AF26: =IFERROR(-ABS(INDEX('frais amazon 011225-150326'!H:H,MATCH(Reproting_ERPALIN!K26,'frais amazon 011225-150326'!D:D,0))/1.2),"Commande hors la France") -> Commande hors la France | AG26: =IFERROR(AF26*E26/SUMIF($K:$K,K26,$E:$E),0) -> 0 | AH26: =AG26/E26 -> 0 | AI26: =AH26+AC26 -> -0.12803333 | AJ26: =AI26/R26 -> -0.857749 | AK26: =AI26*E26 -> -38.41
A27: Aiguille d'injection sans phtalate - Boite de 100 pièces - 22G - 30 mm | B27: IN-07X30 | C27: ZARYS International Group sp. z o.o. sp.k. | D27: 2026-01-01 | E27: 100 | F27: 12.05 | G27: 4.99 | H27: 11.35 | I27: 94.19 | J27: FR | K27: 408-8373165-8705937 | L27: =MONTH(D27) -> 1 | M27: =YEAR(D27) -> 2026 | N27: =D27*1 -> 46023 | O27: =F27/E27 -> 0.1205 | P27: =O27*E27 -> 12.05 | Q27: =G27/E27 -> 0.0499 | R27: =O27+Q27 -> 0.1704 | S27: =R27*E27 -> 17.04 | T27: =-(F27-H27)/E27 -> -0.007 | U27: =R27+T27 -> 0.1634 | V27: =U27*E27 -> 16.34 | W27: =SUMIF(GLS!B:B,K27,GLS!C:C) -> 5.25 | Z27: =-IF(W27+X27+Y27=0,"à vérifier",W27+X27+Y27) -> -5.25 | AA27: =IFERROR((SUMIF($K:$K,K27,$Z:$Z)/COUNTIF($K:$K,K27))*E27/SUMIF($K:$K,K27,$E:$E),0) -> -5.25 | AB27: =AA27/E27 -> -0.0525 | AC27: =AB27+U27 -> 0.1109 | AD27: =AC27/R27 -> 0.6508216 | AE27: =AC27*E27 -> 11.09 | AF27: =IFERROR(-ABS(INDEX('frais amazon 011225-150326'!H:H,MATCH(Reproting_ERPALIN!K27,'frais amazon 011225-150326'!D:D,0))/1.2),"Commande hors la France") -> -3.15 | AG27: =IFERROR(AF27*E27/SUMIF($K:$K,K27,$E:$E),0) -> -3.15 | AH27: =AG27/E27 -> -0.0315 | AI27: =AH27+AC27 -> 0.0794 | AJ27: =AI27/R27 -> 0.46596244 | AK27: =AI27*E27 -> 7.94
A28: Comed - Abaisse langue en bois adulte (Boite de 100 pièces) | B28: 25 105 00 | C28: COMED | D28: 2026-01-01 | E28: 100 | F28: 6.23 | G28: 0 | H28: 4.62 | I28: 74.16 | J28: FR | K28: 408-8368946-2157146 | L28: =MONTH(D28) -> 1 | M28: =YEAR(D28) -> 2026 | N28: =D28*1 -> 46023 | O28: =F28/E28 -> 0.0623 | P28: =O28*E28 -> 6.23 | Q28: =G28/E28 -> 0 | R28: =O28+Q28 -> 0.0623 | S28: =R28*E28 -> 6.23 | T28: =-(F28-H28)/E28 -> -0.0161 | U28: =R28+T28 -> 0.0462 | V28: =U28*E28 -> 4.62 | W28: =SUMIF(GLS!B:B,K28,GLS!C:C) -> 5.25 | Z28: =-IF(W28+X28+Y28=0,"à vérifier",W28+X28+Y28) -> -5.25 | AA28: =IFERROR((SUMIF($K:$K,K28,$Z:$Z)/COUNTIF($K:$K,K28))*E28/SUMIF($K:$K,K28,$E:$E),0) -> -5.25 | AB28: =AA28/E28 -> -0.0525 | AC28: =AB28+U28 -> -0.0063 | AD28: =AC28/R28 -> -0.1011236 | AE28: =AC28*E28 -> -0.63 | AF28: =IFERROR(-ABS(INDEX('frais amazon 011225-150326'!H:H,MATCH(Reproting_ERPALIN!K28,'frais amazon 011225-150326'!D:D,0))/1.2),"Commande hors la France") -> -0.61666667 | AG28: =IFERROR(AF28*E28/SUMIF($K:$K,K28,$E:$E),0) -> -0.61666667 | AH28: =AG28/E28 -> -0.0061666667 | AI28: =AH28+AC28 -> -0.012466667 | AJ28: =AI28/R28 -> -0.20010701 | AK28: =AI28*E28 -> -1.2466667
A29: Pied A Serum 2 Crochets Inox | B29: 45 410 05 | C29: Hartmann | D29: 2026-01-01 | E29: 2 | F29: 143.48 | G29: 4.99 | H29: 49.48 | I29: 34.49 | J29: FR | K29: 408-8166202-4187523 | L29: =MONTH(D29) -> 1 | M29: =YEAR(D29) -> 2026 | N29: =D29*1 -> 46023 | O29: =F29/E29 -> 71.74 | P29: =O29*E29 -> 143.48 | Q29: =G29/E29 -> 2.495 | R29: =O29+Q29 -> 74.235 | S29: =R29*E29 -> 148.47 | T29: =-(F29-H29)/E29 -> -47 | U29: =R29+T29 -> 27.235 | V29: =U29*E29 -> 54.47 | W29: =SUMIF(GLS!B:B,K29,GLS!C:C) -> 0 | Z29: =-IF(W29+X29+Y29=0,"à vérifier",W29+X29+Y29) -> #VALUE! | AA29: =IFERROR((SUMIF($K:$K,K29,$Z:$Z)/COUNTIF($K:$K,K29))*E29/SUMIF($K:$K,K29,$E:$E),0) -> 0 | AB29: =AA29/E29 -> 0 | AC29: =AB29+U29 -> 27.235 | AD29: =AC29/R29 -> 0.36687546 | AE29: =AC29*E29 -> 54.47 | AF29: =IFERROR(-ABS(INDEX('frais amazon 011225-150326'!H:H,MATCH(Reproting_ERPALIN!K29,'frais amazon 011225-150326'!D:D,0))/1.2),"Commande hors la France") -> -27.516667 | AG29: =IFERROR(AF29*E29/SUMIF($K:$K,K29,$E:$E),0) -> -27.516667 | AH29: =AG29/E29 -> -13.758333 | AI29: =AH29+AC29 -> 13.476667 | AJ29: =AI29/R29 -> 0.1815406 | AK29: =AI29*E29 -> 26.953333
A30: Abena - Couches adulte intraversables Maternity Pad Super - Sachet de 15 pièces | B30: 1000022654 | C30: Abena | D30: 2026-01-01 | E30: 30 | F30: 14.35 | G30: 0 | H30: 10.08 | I30: 70.21 | J30: FR | K30: 408-8116156-3541903 | L30: =MONTH(D30) -> 1 | M30: =YEAR(D30) -> 2026 | N30: =D30*1 -> 46023 | O30: =F30/E30 -> 0.47833333 | P30: =O30*E30 -> 14.35 | Q30: =G30/E30 -> 0 | R30: =O30+Q30 -> 0.47833333 | S30: =R30*E30 -> 14.35 | T30: =-(F30-H30)/E30 -> -0.14233333 | U30: =R30+T30 -> 0.336 | V30: =U30*E30 -> 10.08 | W30: =SUMIF(GLS!B:B,K30,GLS!C:C) -> 5.48 | Z30: =-IF(W30+X30+Y30=0,"à vérifier",W30+X30+Y30) -> -5.48 | AA30: =IFERROR((SUMIF($K:$K,K30,$Z:$Z)/COUNTIF($K:$K,K30))*E30/SUMIF($K:$K,K30,$E:$E),0) -> -5.48 | AB30: =AA30/E30 -> -0.18266667 | AC30: =AB30+U30 -> 0.15333333 | AD30: =AC30/R30 -> 0.32055749 | AE30: =AC30*E30 -> 4.6 | AF30: =IFERROR(-ABS(INDEX('frais amazon 011225-150326'!H:H,MATCH(Reproting_ERPALIN!K30,'frais amazon 011225-150326'!D:D,0))/1.2),"Commande hors la France") -> -2.65 | AG30: =IFERROR(AF30*E30/SUMIF($K:$K,K30,$E:$E),0) -> -2.65 | AH30: =AG30/E30 -> -0.088333333 | AI30: =AH30+AC30 -> 0.065 | AJ30: =AI30/R30 -> 0.1358885 | AK30: =AI30*E30 -> 1.95
A31: ZARYS - Sonde béquillée TIEMANN- CH14, (Boite de 50 pièces) | B31: CT-14-40 | C31: ZARYS International Group sp. z o.o. sp.k. | D31: 2026-01-01 | E31: 50 | F31: 25.14 | G31: 4.99 | H31: 18.85 | I31: 74.98 | J31: FR | K31: 408-8021122-5188353 | L31: =MONTH(D31) -> 1 | M31: =YEAR(D31) -> 2026 | N31: =D31*1 -> 46023 | O31: =F31/E31 -> 0.5028 | P31: =O31*E31 -> 25.14 | Q31: =G31/E31 -> 0.0998 | R31: =O31+Q31 -> 0.6026 | S31: =R31*E31 -> 30.13 | T31: =-(F31-H31)/E31 -> -0.1258 | U31: =R31+T31 -> 0.4768 | V31: =U31*E31 -> 23.84 | W31: =SUMIF(GLS!B:B,K31,GLS!C:C) -> 5.25 | Z31: =-IF(W31+X31+Y31=0,"à vérifier",W31+X31+Y31) -> -5.25 | AA31: =IFERROR((SUMIF($K:$K,K31,$Z:$Z)/COUNTIF($K:$K,K31))*E31/SUMIF($K:$K,K31,$E:$E),0) -> -5.25 | AB31: =AA31/E31 -> -0.105 | AC31: =AB31+U31 -> 0.3718 | AD31: =AC31/R31 -> 0.61699303 | AE31: =AC31*E31 -> 18.59 | AF31: =IFERROR(-ABS(INDEX('frais amazon 011225-150326'!H:H,MATCH(Reproting_ERPALIN!K31,'frais amazon 011225-150326'!D:D,0))/1.2),"Commande hors la France") -> -5.575 | AG31: =IFERROR(AF31*E31/SUMIF($K:$K,K31,$E:$E),0) -> -5.575 | AH31: =AG31/E31 -> -0.1115 | AI31: =AH31+AC31 -> 0.2603 | AJ31: =AI31/R31 -> 0.4319615 | AK31: =AI31*E31 -> 13.015
A32: Seringue à usage unique, 3 parties, Luer Lock de 50 ml, (Boite de 25 pièces) | B32: 050ML-3CZ-LL-PI | C32: ZARYS International Group sp. z o.o. sp.k. | D32: 2026-01-01 | E32: 25 | F32: 17.94 | G32: 4.99 | H32: 14.65 | I32: 81.66 | J32: FR | K32: 408-7962812-0682700 | L32: =MONTH(D32) -> 1 | M32: =YEAR(D32) -> 2026 | N32: =D32*1 -> 46023 | O32: =F32/E32 -> 0.7176 | P32: =O32*E32 -> 17.94 | Q32: =G32/E32 -> 0.1996 | R32: =O32+Q32 -> 0.9172 | S32: =R32*E32 -> 22.93 | T32: =-(F32-H32)/E32 -> -0.1316 | U32: =R32+T32 -> 0.7856 | V32: =U32*E32 -> 19.64 | W32: =SUMIF(GLS!B:B,K32,GLS!C:C) -> 5.48 | Z32: =-IF(W32+X32+Y32=0,"à vérifier",W32+X32+Y32) -> -5.48 | AA32: =IFERROR((SUMIF($K:$K,K32,$Z:$Z)/COUNTIF($K:$K,K32))*E32/SUMIF($K:$K,K32,$E:$E),0) -> -5.48 | AB32: =AA32/E32 -> -0.2192 | AC32: =AB32+U32 -> 0.5664 | AD32: =AC32/R32 -> 0.61753162 | AE32: =AC32*E32 -> 14.16 | AF32: =IFERROR(-ABS(INDEX('frais amazon 011225-150326'!H:H,MATCH(Reproting_ERPALIN!K32,'frais amazon 011225-150326'!D:D,0))/1.2),"Commande hors la France") -> -4.25 | AG32: =IFERROR(AF32*E32/SUMIF($K:$K,K32,$E:$E),0) -> -4.25 | AH32: =AG32/E32 -> -0.17 | AI32: =AH32+AC32 -> 0.3964 | AJ32: =AI32/R32 -> 0.43218491 | AK32: =AI32*E32 -> 9.91
A33: Aiguille hypodermique à usage unique non sécurisée 25G, 0,5 mm x 40 mm | B33: IN-05X40 | C33: ZARYS International Group sp. z o.o. sp.k. | D33: 2026-01-01 | E33: 100 | F33: 10.72 | G33: 4.99 | H33: 9.85 | I33: 91.88 | J33: FR | K33: 408-7942697-7501904 | L33: =MONTH(D33) -> 1 | M33: =YEAR(D33) -> 2026 | N33: =D33*1 -> 46023 | O33: =F33/E33 -> 0.1072 | P33: =O33*E33 -> 10.72 | Q33: =G33/E33 -> 0.0499 | R33: =O33+Q33 -> 0.1571 | S33: =R33*E33 -> 15.71 | T33: =-(F33-H33)/E33 -> -0.0087 | U33: =R33+T33 -> 0.1484 | V33: =U33*E33 -> 14.84 | W33: =SUMIF(GLS!B:B,K33,GLS!C:C) -> 5.25 | Z33: =-IF(W33+X33+Y33=0,"à vérifier",W33+X33+Y33) -> -5.25 | AA33: =IFERROR((SUMIF($K:$K,K33,$Z:$Z)/COUNTIF($K:$K,K33))*E33/SUMIF($K:$K,K33,$E:$E),0) -> -5.25 | AB33: =AA33/E33 -> -0.0525 | AC33: =AB33+U33 -> 0.0959 | AD33: =AC33/R33 -> 0.61043921 | AE33: =AC33*E33 -> 9.59 | AF33: =IFERROR(-ABS(INDEX('frais amazon 011225-150326'!H:H,MATCH(Reproting_ERPALIN!K33,'frais amazon 011225-150326'!D:D,0))/1.2),"Commande hors la France") -> -2.9166667 | AG33: =IFERROR(AF33*E33/SUMIF($K:$K,K33,$E:$E),0) -> -2.9166667 | AH33: =AG33/E33 -> -0.029166667 | AI33: =AH33+AC33 -> 0.066733333 | AJ33: =AI33/R33 -> 0.42478252 | AK33: =AI33*E33 -> 6.6733333
A34: ZARYS - Seringue à usage unique en 3 parties luer avec aiguille stérile 2 ml buse centrique 0.6mm x 30mm bleu foncé - Boite de 100 pcs | B34: 002ML-3CZ-SN | C34: ZARYS International Group sp. z o.o. sp.k. | D34: 2026-01-01 | E34: 100 | F34: 9.48 | G34: 4.99 | H34: 7.34 | I34: 77.43 | J34: FR | K34: 408-7746100-0015500 | L34: =MONTH(D34) -> 1 | M34: =YEAR(D34) -> 2026 | N34: =D34*1 -> 46023 | O34: =F34/E34 -> 0.0948 | P34: =O34*E34 -> 9.48 | Q34: =G34/E34 -> 0.0499 | R34: =O34+Q34 -> 0.1447 | S34: =R34*E34 -> 14.47 | T34: =-(F34-H34)/E34 -> -0.0214 | U34: =R34+T34 -> 0.1233 | V34: =U34*E34 -> 12.33 | W34: =SUMIF(GLS!B:B,K34,GLS!C:C) -> 5.25 | Z34: =-IF(W34+X34+Y34=0,"à vérifier",W34+X34+Y34) -> -5.25 | AA34: =IFERROR((SUMIF($K:$K,K34,$Z:$Z)/COUNTIF($K:$K,K34))*E34/SUMIF($K:$K,K34,$E:$E),0) -> -5.25 | AB34: =AA34/E34 -> -0.0525 | AC34: =AB34+U34 -> 0.0708 | AD34: =AC34/R34 -> 0.48928818 | AE34: =AC34*E34 -> 7.08 | AF34: =IFERROR(-ABS(INDEX('frais amazon 011225-150326'!H:H,MATCH(Reproting_ERPALIN!K34,'frais amazon 011225-150326'!D:D,0))/1.2),"Commande hors la France") -> -2.675 | AG34: =IFERROR(AF34*E34/SUMIF($K:$K,K34,$E:$E),0) -> -2.675 | AH34: =AG34/E34 -> -0.02675 | AI34: =AH34+AC34 -> 0.04405 | AJ34: =AI34/R34 -> 0.30442294 | AK34: =AI34*E34 -> 4.405
A35: Aiguille d'injection sans phtalate - Boite de 100 pièces - 25G - 25 mm | B35: IN-05X25 | C35: ZARYS International Group sp. z o.o. sp.k. | D35: 2026-01-01 | E35: 100 | F35: 10.05 | G35: 11.38 | H35: 9.27 | I35: 92.24 | J35: IE | K35: 408-7714441-4337122 | L35: =MONTH(D35) -> 1 | M35: =YEAR(D35) -> 2026 | N35: =D35*1 -> 46023 | O35: =F35/E35 -> 0.1005 | P35: =O35*E35 -> 10.05 | Q35: =G35/E35 -> 0.1138 | R35: =O35+Q35 -> 0.2143 | S35: =R35*E35 -> 21.43 | T35: =-(F35-H35)/E35 -> -0.0078 | U35: =R35+T35 -> 0.2065 | V35: =U35*E35 -> 20.65 | W35: =SUMIF(GLS!B:B,K35,GLS!C:C) -> 11.72 | Z35: =-IF(W35+X35+Y35=0,"à vérifier",W35+X35+Y35) -> -11.72 | AA35: =IFERROR((SUMIF($K:$K,K35,$Z:$Z)/COUNTIF($K:$K,K35))*E35/SUMIF($K:$K,K35,$E:$E),0) -> -11.72 | AB35: =AA35/E35 -> -0.1172 | AC35: =AB35+U35 -> 0.0893 | AD35: =AC35/R35 -> 0.41670555 | AE35: =AC35*E35 -> 8.93 | AF35: =IFERROR(-ABS(INDEX('frais amazon 011225-150326'!H:H,MATCH(Reproting_ERPALIN!K35,'frais amazon 011225-150326'!D:D,0))/1.2),"Commande hors la France") -> Commande hors la France | AG35: =IFERROR(AF35*E35/SUMIF($K:$K,K35,$E:$E),0) -> 0 | AH35: =AG35/E35 -> 0 | AI35: =AH35+AC35 -> 0.0893 | AJ35: =AI35/R35 -> 0.41670555 | AK35: =AI35*E35 -> 8.93
A36: Aiguille d'injection sans phtalate - Boite de 100 pièces - 23G - 30 mm | B36: IN-06X30 | C36: ZARYS International Group sp. z o.o. sp.k. | D36: 2026-01-01 | E36: 100 | F36: 10.47 | G36: 8.75 | H36: 9.7 | I36: 92.65 | J36: ES | K36: 408-7640878-0907507 | L36: =MONTH(D36) -> 1 | M36: =YEAR(D36) -> 2026 | N36: =D36*1 -> 46023 | O36: =F36/E36 -> 0.1047 | P36: =O36*E36 -> 10.47 | Q36: =G36/E36 -> 0.0875 | R36: =O36+Q36 -> 0.1922 | S36: =R36*E36 -> 19.22 | T36: =-(F36-H36)/E36 -> -0.0077 | U36: =R36+T36 -> 0.1845 | V36: =U36*E36 -> 18.45 | W36: =SUMIF(GLS!B:B,K36,GLS!C:C) -> 10.72 | Z36: =-IF(W36+X36+Y36=0,"à vérifier",W36+X36+Y36) -> -10.72 | AA36: =IFERROR((SUMIF($K:$K,K36,$Z:$Z)/COUNTIF($K:$K,K36))*E36/SUMIF($K:$K,K36,$E:$E),0) -> -10.72 | AB36: =AA36/E36 -> -0.1072 | AC36: =AB36+U36 -> 0.0773 | AD36: =AC36/R36 -> 0.40218522 | AE36: =AC36*E36 -> 7.73 | AF36: =IFERROR(-ABS(INDEX('frais amazon 011225-150326'!H:H,MATCH(Reproting_ERPALIN!K36,'frais amazon 011225-150326'!D:D,0))/1.2),"Commande hors la France") -> Commande hors la France | AG36: =IFERROR(AF36*E36/SUMIF($K:$K,K36,$E:$E),0) -> 0 | AH36: =AG36/E36 -> 0 | AI36: =AH36+AC36 -> 0.0773 | AJ36: =AI36/R36 -> 0.40218522 | AK36: =AI36*E36 -> 7.73
A37: Abena - Gants d'examen nitrile en bleu non poudrés 240mm - Classic - Boite de 100 pièces L | B37: 1999905274 | C37: Abena | D37: 2025-12-01 | E37: 1000 | F37: 30.7 | G37: 4.99 | H37: 13.5 | I37: 43.97 | J37: FR | K37: 408-7640860-0578732 | L37: =MONTH(D37) -> 12 | M37: =YEAR(D37) -> 2025 | N37: =D37*1 -> 45992 | O37: =F37/E37 -> 0.0307 | P37: =O37*E37 -> 30.7 | Q37: =G37/E37 -> 0.00499 | R37: =O37+Q37 -> 0.03569 | S37: =R37*E37 -> 35.69 | T37: =-(F37-H37)/E37 -> -0.0172 | U37: =R37+T37 -> 0.01849 | V37: =U37*E37 -> 18.49 | W37: =SUMIF(GLS!B:B,K37,GLS!C:C) -> 6.13 | Z37: =-IF(W37+X37+Y37=0,"à vérifier",W37+X37+Y37) -> -6.13 | AA37: =IFERROR((SUMIF($K:$K,K37,$Z:$Z)/COUNTIF($K:$K,K37))*E37/SUMIF($K:$K,K37,$E:$E),0) -> -6.13 | AB37: =AA37/E37 -> -0.00613 | AC37: =AB37+U37 -> 0.01236 | AD37: =AC37/R37 -> 0.34631549 | AE37: =AC37*E37 -> 12.36 | AF37: =IFERROR(-ABS(INDEX('frais amazon 011225-150326'!H:H,MATCH(Reproting_ERPALIN!K37,'frais amazon 011225-150326'!D:D,0))/1.2),"Commande hors la France") -> -6.425 | AG37: =IFERROR(AF37*E37/SUMIF($K:$K,K37,$E:$E),0) -> -6.425 | AH37: =AG37/E37 -> -0.006425 | AI37: =AH37+AC37 -> 0.005935 | AJ37: =AI37/R37 -> 0.16629308 | AK37: =AI37*E37 -> 5.935
A38: Aiguille d'injection sans phtalate - Boite de 100 pièces - 22G - 30 mm | B38: IN-07X30 | C38: ZARYS International Group sp. z o.o. sp.k. | D38: 2026-01-01 | E38: 100 | F38: 12.05 | G38: 4.99 | H38: 11.35 | I38: 94.19 | J38: FR | K38: 408-7491984-3217121 | L38: =MONTH(D38) -> 1 | M38: =YEAR(D38) -> 2026 | N38: =D38*1 -> 46023 | O38: =F38/E38 -> 0.1205 | P38: =O38*E38 -> 12.05 | Q38: =G38/E38 -> 0.0499 | R38: =O38+Q38 -> 0.1704 | S38: =R38*E38 -> 17.04 | T38: =-(F38-H38)/E38 -> -0.007 | U38: =R38+T38 -> 0.1634 | V38: =U38*E38 -> 16.34 | W38: =SUMIF(GLS!B:B,K38,GLS!C:C) -> 5.49 | Z38: =-IF(W38+X38+Y38=0,"à vérifier",W38+X38+Y38) -> -5.49 | AA38: =IFERROR((SUMIF($K:$K,K38,$Z:$Z)/COUNTIF($K:$K,K38))*E38/SUMIF($K:$K,K38,$E:$E),0) -> -5.49 | AB38: =AA38/E38 -> -0.0549 | AC38: =AB38+U38 -> 0.1085 | AD38: =AC38/R38 -> 0.63673709 | AE38: =AC38*E38 -> 10.85 | AF38: =IFERROR(-ABS(INDEX('frais amazon 011225-150326'!H:H,MATCH(Reproting_ERPALIN!K38,'frais amazon 011225-150326'!D:D,0))/1.2),"Commande hors la France") -> -3.1666667 | AG38: =IFERROR(AF38*E38/SUMIF($K:$K,K38,$E:$E),0) -> -3.1666667 | AH38: =AG38/E38 -> -0.031666667 | AI38: =AH38+AC38 -> 0.076833333 | AJ38: =AI38/R38 -> 0.45089984 | AK38: =AI38*E38 -> 7.6833333
A39: Aiguille hypodermique à usage unique non sécurisée 25G, 0,5 mm x 40 mm | B39: IN-05X40 | C39: ZARYS International Group sp. z o.o. sp.k. | D39: 2026-01-01 | E39: 100 | F39: 10.72 | G39: 4.99 | H39: 9.85 | I39: 91.88 | J39: FR | K39: 408-7271559-7642744 | L39: =MONTH(D39) -> 1 | M39: =YEAR(D39) -> 2026 | N39: =D39*1 -> 46023 | O39: =F39/E39 -> 0.1072 | P39: =O39*E39 -> 10.72 | Q39: =G39/E39 -> 0.0499 | R39: =O39+Q39 -> 0.1571 | S39: =R39*E39 -> 15.71 | T39: =-(F39-H39)/E39 -> -0.0087 | U39: =R39+T39 -> 0.1484 | V39: =U39*E39 -> 14.84 | W39: =SUMIF(GLS!B:B,K39,GLS!C:C) -> 5.25 | Z39: =-IF(W39+X39+Y39=0,"à vérifier",W39+X39+Y39) -> -5.25 | AA39: =IFERROR((SUMIF($K:$K,K39,$Z:$Z)/COUNTIF($K:$K,K39))*E39/SUMIF($K:$K,K39,$E:$E),0) -> -5.25 | AB39: =AA39/E39 -> -0.0525 | AC39: =AB39+U39 -> 0.0959 | AD39: =AC39/R39 -> 0.61043921 | AE39: =AC39*E39 -> 9.59 | AF39: =IFERROR(-ABS(INDEX('frais amazon 011225-150326'!H:H,MATCH(Reproting_ERPALIN!K39,'frais amazon 011225-150326'!D:D,0))/1.2),"Commande hors la France") -> -2.9166667 | AG39: =IFERROR(AF39*E39/SUMIF($K:$K,K39,$E:$E),0) -> -2.9166667 | AH39: =AG39/E39 -> -0.029166667 | AI39: =AH39+AC39 -> 0.066733333 | AJ39: =AI39/R39 -> 0.42478252 | AK39: =AI39*E39 -> 6.6733333
A40: Abena - Couches adulte intraversables Maternity Pad Super - Sachet de 15 pièces | B40: 1000022654 | C40: Abena | D40: 2026-01-01 | E40: 15 | F40: 6.93 | G40: 4.99 | H40: 4.79 | I40: 69.16 | J40: FR | K40: 408-7121406-3360337 | L40: =MONTH(D40) -> 1 | M40: =YEAR(D40) -> 2026 | N40: =D40*1 -> 46023 | O40: =F40/E40 -> 0.462 | P40: =O40*E40 -> 6.93 | Q40: =G40/E40 -> 0.33266667 | R40: =O40+Q40 -> 0.79466667 | S40: =R40*E40 -> 11.92 | T40: =-(F40-H40)/E40 -> -0.14266667 | U40: =R40+T40 -> 0.652 | V40: =U40*E40 -> 9.78 | W40: =SUMIF(GLS!B:B,K40,GLS!C:C) -> 5.25 | Z40: =-IF(W40+X40+Y40=0,"à vérifier",W40+X40+Y40) -> -5.25 | AA40: =IFERROR((SUMIF($K:$K,K40,$Z:$Z)/COUNTIF($K:$K,K40))*E40/SUMIF($K:$K,K40,$E:$E),0) -> -5.25 | AB40: =AA40/E40 -> -0.35 | AC40: =AB40+U40 -> 0.302 | AD40: =AC40/R40 -> 0.38003356 | AE40: =AC40*E40 -> 4.53 | AF40: =IFERROR(-ABS(INDEX('frais amazon 011225-150326'!H:H,MATCH(Reproting_ERPALIN!K40,'frais amazon 011225-150326'!D:D,0))/1.2),"Commande hors la France") -> -2.2083333 | AG40: =IFERROR(AF40*E40/SUMIF($K:$K,K40,$E:$E),0) -> -2.2083333 | AH40: =AG40/E40 -> -0.14722222 | AI40: =AH40+AC40 -> 0.15477778 | AJ40: =AI40/R40 -> 0.19477069 | AK40: =AI40*E40 -> 2.3216667
...

Sheet frais amazon 011225-150326
A1: Date | B1: Statut de la transaction | C1: Type de transaction | D1: Numéro de la commande | E1: Détails sur le produit | F1: Total des frais produit | G1: Total des rabais promotionnels | H1: Commissions Amazon | I1: Autres | J1: Total (EUR)
A2: 46096 | B2: Sorti | C2: Paiement de la commande | D2: 408-7107728-4926706 | E2: MoliCare Premium Elastic Slip : 10 goutt... | F2: 18 | G2: 0 | H2: -4.01 | I2: 3.6 | J2: 17.59
A3: 46096 | B3: Sorti | C3: Paiement de la commande | D3: 402-8980354-7775534 | E3: Abena Premium Lot de 2x14 serviettes hyg... | F3: 13.53 | G3: 0 | H3: -3 | I3: 2.71 | J3: 13.24
A4: 46096 | B4: Sorti | C4: Paiement de la commande | D4: 405-0206505-2222716 | E4: Abena Premium Lot de 2x14 serviettes hyg... | F4: 13.53 | G4: 0 | H4: -3 | I4: 2.71 | J4: 13.24
A5: 46096 | B5: Sorti | C5: Paiement de la commande | D5: 408-1635227-2411501 | E5: iD Intime Pants Normal Discret et Confor... | F5: 11.75 | G5: 0 | H5: -3.73 | I5: 8.34 | J5: 16.36
A6: 46096 | B6: Sorti | C6: Paiement de la commande | D6: 403-7237882-4667552 | E6: Blouse visiteur jetable - Lot de 40 | F6: 19.2 | G6: 0 | H6: -4.28 | I6: 3.84 | J6: 18.76
A7: 46096 | B7: Sorti | C7: Remboursement | D7: 171-9729146-8673155 | E7: Aiguille d'injection de sécurité, stéril... | F7: -8.76 | G7: 0 | H7: 2.45 | I7: -7.74 | J7: -14.05
A8: 46096 | B8: Sorti | C8: Paiement de la commande | D8: 171-9729146-8673155 | E8: Aiguille d'injection de sécurité, stéril... | F8: 8.76 | G8: 0 | H8: -3.05 | I8: 7.74 | J8: 13.45
A9: 46096 | B9: Sorti | C9: Paiement de la commande | D9: 406-6036257-1683508 | E9: KIBERTIC - 100 Pcs Tablier Plastique Jet... | F9: 27.9 | G9: 0 | H9: -2.02 | I9: 5.58 | J9: 31.46
A10: 46095 | B10: Sorti | C10: Paiement de la commande | D10: 405-5177594-4800327 | E10: Abena Premium Lot de 2x14 serviettes hyg... | F10: 13.53 | G10: 0 | H10: -3.02 | I10: 2.71 | J10: 13.22
A11: 46095 | B11: Sorti | C11: Solde non disponible | D11: --- | E11: Montant de la réserve actuelle | F11: 0 | G11: 0 | H11: 0 | I11: -749.94 | J11: -749.94
A12: 46095 | B12: Sorti | C12: Solde non disponible de la période précédente | D12: --- | E12: Solde du montant de la réserve précédente | F12: 0 | G12: 0 | H12: 0 | I12: 749.94 | J12: 749.94
A13: 46095 | B13: Différé | C13: Paiement de la commande | D13: 402-7877131-5482714 | E13: Seringue stérile Luer Lock CHIRANA 3 piè... | F13: 13.96 | G13: 0 | H13: -3.1 | I13: 2.79 | J13: 13.65
... A326: 46087 | B326: Sorti | C326: Paiement de la commande | D326: 406-1009443-3154763 | E326: Abena Premium Lot de 2x14 serviettes hyg... | F326: 13.53 | G326: 0 | H326: -3.02 | I326: 2.71 | J326: 13.22
A327: 46086 | B327: Sorti | C327: Paiement de la commande | D327: 402-8113032-0362723 | E327: =-LILLE Suprem Fit Extra+ Incontinence mo... -> #NAME? | F327: 19.77 | G327: 0 | H327: -4.4 | I327: 3.96 | J327: 19.33
A328: 46086 | B328: Sorti | C328: Paiement de la commande | D328: 407-6832828-0098739 | E328: Sonde de Foley à deux voies avec valve e... | F328: 16.43 | G328: 0 | H328: -4.77 | I328: 9.28 | J328: 20.94
A329: 46086 | B329: Sorti | C329: Paiement de la commande | D329: 404-2405113-4545904 | E329: MoliCare Premium Elastic Lot de 14 slips... | F329: 80.2 | G329: 0 | H329: -17.85 | I329: 16.04 | J329: 78.39
A330: 46086 | B330: Sorti | C330: Paiement de la commande | D330: 405-3331286-9894718 | E330: Pansement non tissé avec compresse absor... | F330: 14.37 | G330: 0 | H330: -4.29 | I330: 8.86 | J330: 18.94
A331: 46086 | B331: Sorti | C331: Paiement de la commande | D331: 404-6995517-3984333 | E331: Hartmann - Carrés de Soin 50g Octolin - ... | F331: 5.59 | G331: 0 | H331: -1.25 | I331: 7.11 | J331: 11.45
A332: 46086 | B332: Sorti | C332: Paiement de la commande | D332: 402-9514833-3010705 | E332: Molicare Premium Fixpants - Slip de Main... | F332: 8.47 | G332: 0 | H332: -3 | I332: 7.68 | J332: 13.15
A333: 46086 | B333: Sorti | C333: Paiement de la commande | D333: 402-3761586-4925108 | E333: ABENA Slip Premium Lot de 3 paquets de 2... | F333: 97.68 | G333: 0 | H333: -21.74 | I333: 19.54 | J333: 95.48
A334: 46086 | B334: Sorti | C334: Paiement de la commande | D334: 408-1142178-0097115 | E334: Sterilux Pads BIO - Rectangles De Coton ... | F334: 16.26 | G334: 0 | H334: -2.54 | I334: 9.23 | J334: 22.95
A335: 46086 | B335: Sorti | C335: Paiement de la commande | D335: 405-5199459-5829963 | E335: iD Expert Lot de 28 slips taille M super... | F335: 22.14 | G335: 0 | H335: -6.03 | I335: 10.42 | J335: 26.53
A336: 46086 | B336: Sorti | C336: Paiement de la commande | D336: 405-9534028-8448320 | E336: Abena Premium Lot de 2x14 serviettes hyg... | F336: 13.53 | G336: 0 | H336: -3.02 | I336: 2.71 | J336: 13.22
A337: 46086 | B337: Sorti | C337: Paiement de la commande | D337: 407-5775677-3730730 | E337: Zarys Seringue à usage unique en 3 parti... | F337: 21.38 | G337: 0 | H337: -5.86 | I337: 10.27 | J337: 25.79
A338: 46086 | B338: Sorti | C338: Paiement de la commande | D338: 406-3225484-4849966 | E338: Abena Premium Lot de 2x14 serviettes hyg... | F338: 13.53 | G338: 0 | H338: -3.02 | I338: 2.71 | J338: 13.22
A339: 46086 | B339: Sorti | C339: Paiement de la commande | D339: 406-5511120-6409958 | E339: Zarys Seringue à usage unique en 3 parti... | F339: 11.62 | G339: 0 | H339: -3.7 | I339: 8.31 | J339: 16.23
... A2145: 45992 | B2145: Sorti | C2145: Remboursement | D2145: 402-4814753-1215527 | E2145: Lille Classic Bed Extra 60 x 90 cm - Car... | F2145: -56.76 | G2145: 0 | H2145: 11.09 | I2145: -17.34 | J2145: -63.01

Sheet GLS
A1: NumÃ©ro de colis | B1: Client RÃ©fÃ©rence 1 | C1: Total facturé
A2: 00KEHAT6 | B2: 8869 | C2: 3.5 | D2: =IF(COUNTIFS(A:A,A2,B:B,B2,C:C,C2)>1,"Doublon","Unique") -> Unique
A3: 00KIXPSK | B3: WS160321 | C3: 6.7 | D3: =IF(COUNTIFS(A:A,A3,B:B,B3,C:C,C3)>1,"Doublon","Unique") -> Unique
A4: 00KI50EZ | B4: 9178 | C4: 6.7 | D4: =IF(COUNTIFS(A:A,A4,B:B,B4,C:C,C4)>1,"Doublon","Unique") -> Unique
A5: 00KI50CU | B5: 9143 | C5: -0.02 | D5: =IF(COUNTIFS(A:A,A5,B:B,B5,C:C,C5)>1,"Doublon","Unique") -> Unique
A6: 00KI50F8 | B6: 9216 | C6: -0.5 | D6: =IF(COUNTIFS(A:A,A6,B:B,B6,C:C,C6)>1,"Doublon","Unique") -> Unique
A7: 00KI50CP | B7: 9139 | C7: -0.5 | D7: =IF(COUNTIFS(A:A,A7,B:B,B7,C:C,C7)>1,"Doublon","Unique") -> Unique
A8: 00KJ48Z5 | B8: 405-4708345-6904338 | C8: 5.48 | D8: =IF(COUNTIFS(A:A,A8,B:B,B8,C:C,C8)>1,"Doublon","Unique") -> Unique
A9: 00KJ48Z5 | B9: 405-4708345-6904338 | C9: 5.25 | D9: =IF(COUNTIFS(A:A,A9,B:B,B9,C:C,C9)>1,"Doublon","Unique") -> Unique
A10: 00KI50FX | B10: 8745 | C10: -0.5 | D10: =IF(COUNTIFS(A:A,A10,B:B,B10,C:C,C10)>1,"Doublon","Unique") -> Unique
A11: 00KI50HR | B11: 8967 | C11: -0.5 | D11: =IF(COUNTIFS(A:A,A11,B:B,B11,C:C,C11)>1,"Doublon","Unique") -> Unique
A12: 00KI50HK | B12: 9319 | C12: -0.5 | D12: =IF(COUNTIFS(A:A,A12,B:B,B12,C:C,C12)>1,"Doublon","Unique") -> Unique
A13: 00KI50F5 | B13: 9208 | C13: -0.5 | D13: =IF(COUNTIFS(A:A,A13,B:B,B13,C:C,C13)>1,"Doublon","Unique") -> Unique
A14: 00KI50CV | B14: 9145 | C14: -0.5 | D14: =IF(COUNTIFS(A:A,A14,B:B,B14,C:C,C14)>1,"Doublon","Unique") -> Unique
A15: 00KI50G7 | B15: 9256 | C15: -0.5 | D15: =IF(COUNTIFS(A:A,A15,B:B,B15,C:C,C15)>1,"Doublon","Unique") -> Unique
A16: 00KIXYSJ | B16: 403-9264929-6249967 | C16: 5.5 | D16: =IF(COUNTIFS(A:A,A16,B:B,B16,C:C,C16)>1,"Doublon","Unique") -> Unique
A17: 00KI50G7 | B17: 9256 | C17: -0.02 | D17: =IF(COUNTIFS(A:A,A17,B:B,B17,C:C,C17)>1,"Doublon","Unique") -> Unique
A18: 00KI50I0 | B18: 9256 | C18: -0.04 | D18: =IF(COUNTIFS(A:A,A18,B:B,B18,C:C,C18)>1,"Doublon","Unique") -> Unique
A19: 00KI50G7 | B19: 9256 | C19: 8.1 | D19: =IF(COUNTIFS(A:A,A19,B:B,B19,C:C,C19)>1,"Doublon","Unique") -> Unique
A20: 00KI50I0 | B20: 9256 | C20: 8.1 | D20: =IF(COUNTIFS(A:A,A20,B:B,B20,C:C,C20)>1,"Doublon","Unique") -> Unique
A21: 00KI50EQ | B21: 9123 | C21: 6.57 | D21: =IF(COUNTIFS(A:A,A21,B:B,B21,C:C,C21)>1,"Doublon","Unique") -> Unique
A22: 00KIW45E | B22: 408-3160821-7768310 | C22: 5.25 | D22: =IF(COUNTIFS(A:A,A22,B:B,B22,C:C,C22)>1,"Doublon","Unique") -> Unique
A23: 00KIXGM9 | B23: 407-2430595-1536334 | C23: 5.25 | D23: =IF(COUNTIFS(A:A,A23,B:B,B23,C:C,C23)>1,"Doublon","Unique") -> Unique
A24: 00KI50HM | B24: 9320 | C24: 5.5 | D24: =IF(COUNTIFS(A:A,A24,B:B,B24,C:C,C24)>1,"Doublon","Unique") -> Unique
A25: 00KIXGUQ | B25: 406-4359445-7162731 | C25: 5.25 | D25: =IF(COUNTIFS(A:A,A25,B:B,B25,C:C,C25)>1,"Doublon","Unique") -> Unique
A26: 00KIXXXY | B26: 408-3376791-7795524 | C26: 5.48 | D26: =IF(COUNTIFS(A:A,A26,B:B,B26,C:C,C26)>1,"Doublon","Unique") -> Unique
A27: 00KIXPSK | B27: WS160321 | C27: -0.5 | D27: =IF(COUNTIFS(A:A,A27,B:B,B27,C:C,C27)>1,"Doublon","Unique") -> Unique
A28: 00KIXPSK | B28: WS160321 | C28: -1 | D28: =IF(COUNTIFS(A:A,A28,B:B,B28,C:C,C28)>1,"Doublon","Unique") -> Unique
A29: 00KI50EC | B29: 9143 | C29: -0.05 | D29: =IF(COUNTIFS(A:A,A29,B:B,B29,C:C,C29)>1,"Doublon","Unique") -> Unique
A30: 00KI50ED | B30: 9143 | C30: -0.05 | D30: =IF(COUNTIFS(A:A,A30,B:B,B30,C:C,C30)>1,"Doublon","Unique") -> Unique
A31: 00KI50CU | B31: 9143 | C31: 6.57 | D31: =IF(COUNTIFS(A:A,A31,B:B,B31,C:C,C31)>1,"Doublon","Unique") -> Unique
A32: 00KI50EC | B32: 9143 | C32: 6.84 | D32: =IF(COUNTIFS(A:A,A32,B:B,B32,C:C,C32)>1,"Doublon","Unique") -> Unique
A33: 00KI50ED | B33: 9143 | C33: 8.38 | D33: =IF(COUNTIFS(A:A,A33,B:B,B33,C:C,C33)>1,"Doublon","Unique") -> Unique
A34: 00KI50DY | B34: 9187 | C34: 6.84 | D34: =IF(COUNTIFS(A:A,A34,B:B,B34,C:C,C34)>1,"Doublon","Unique") -> Unique
A35: 00KI50BW | B35: 8819 | C35: 5.25 | D35: =IF(COUNTIFS(A:A,A35,B:B,B35,C:C,C35)>1,"Doublon","Unique") -> Unique
A36: 00KI50G1 | B36: 9249 | C36: 5.25 | D36: =IF(COUNTIFS(A:A,A36,B:B,B36,C:C,C36)>1,"Doublon","Unique") -> Unique
A37: 00KI50FM | B37: 9232 | C37: 5.48 | D37: =IF(COUNTIFS(A:A,A37,B:B,B37,C:C,C37)>1,"Doublon","Unique") -> Unique
A38: 00KI50CU | B38: 9143 | C38: -0.5 | D38: =IF(COUNTIFS(A:A,A38,B:B,B38,C:C,C38)>1,"Doublon","Unique") -> Unique
A39: 00KI50HF | B39: 9316 | C39: -0.5 | D39: =IF(COUNTIFS(A:A,A39,B:B,B39,C:C,C39)>1,"Doublon","Unique") -> Unique
A40: 00KI50D8 | B40: 9157 | C40: -0.5 | D40: =IF(COUNTIFS(A:A,A40,B:B,B40,C:C,C40)>1,"Doublon","Unique") -> Unique
...

Sheet Analyse ==>

Sheet Parametres_Dates
A2: Date début | B2: 45962
A3: Date de fin | B3: 46142

Sheet Classement des produits
A1: SKU du produit | B1: CA sur la période | C1: Classement
A2: IN-08X50 | B2: =SUMIFS(Reproting_ERPALIN!S:S,Reproting_ERPALIN!B:B,'Classement des produits'!A2,Reproting_ERPALIN!N:N,">"&Parametres_Dates!$B$2,Reproting_ERPALIN!$N:$N,"<="&Parametres_Dates!$B$3) -> 512.84333 | C2: =RANK(B2,$B$2:$B$234) -> 9
A3: IN-05X40 | B3: =SUMIFS(Reproting_ERPALIN!S:S,Reproting_ERPALIN!B:B,'Classement des produits'!A3,Reproting_ERPALIN!N:N,">"&Parametres_Dates!$B$2,Reproting_ERPALIN!$N:$N,"<="&Parametres_Dates!$B$3) -> 799.40833 | C3: =RANK(B3,$B$2:$B$234) -> 4
A4: CH03010LL | B4: =SUMIFS(Reproting_ERPALIN!S:S,Reproting_ERPALIN!B:B,'Classement des produits'!A4,Reproting_ERPALIN!N:N,">"&Parametres_Dates!$B$2,Reproting_ERPALIN!$N:$N,"<="&Parametres_Dates!$B$3) -> 394.73333 | C4: =RANK(B4,$B$2:$B$234) -> 10
A5: CH18200 | B5: =SUMIFS(Reproting_ERPALIN!S:S,Reproting_ERPALIN!B:B,'Classement des produits'!A5,Reproting_ERPALIN!N:N,">"&Parametres_Dates!$B$2,Reproting_ERPALIN!$N:$N,"<="&Parametres_Dates!$B$3) -> 15.92 | C5: =RANK(B5,$B$2:$B$234) -> 192
A6: 1000022654 | B6: =SUMIFS(Reproting_ERPALIN!S:S,Reproting_ERPALIN!B:B,'Classement des produits'!A6,Reproting_ERPALIN!N:N,">"&Parametres_Dates!$B$2,Reproting_ERPALIN!$N:$N,"<="&Parametres_Dates!$B$3) -> 2219.89 | C6: =RANK(B6,$B$2:$B$234) -> 1
A7: 413772 | B7: =SUMIFS(Reproting_ERPALIN!S:S,Reproting_ERPALIN!B:B,'Classement des produits'!A7,Reproting_ERPALIN!N:N,">"&Parametres_Dates!$B$2,Reproting_ERPALIN!$N:$N,"<="&Parametres_Dates!$B$3) -> 147.54 | C7: =RANK(B7,$B$2:$B$234) -> 37
A8: NL105-S-40 | B8: =SUMIFS(Reproting_ERPALIN!S:S,Reproting_ERPALIN!B:B,'Classement des produits'!A8,Reproting_ERPALIN!N:N,">"&Parametres_Dates!$B$2,Reproting_ERPALIN!$N:$N,"<="&Parametres_Dates!$B$3) -> 35.04 | C8: =RANK(B8,$B$2:$B$234) -> 132
A9: 931305 | B9: =SUMIFS(Reproting_ERPALIN!S:S,Reproting_ERPALIN!B:B,'Classement des produits'!A9,Reproting_ERPALIN!N:N,">"&Parametres_Dates!$B$2,Reproting_ERPALIN!$N:$N,"<="&Parametres_Dates!$B$3) -> 18.71 | C9: =RANK(B9,$B$2:$B$234) -> 184
A10: 684358 | B10: =SUMIFS(Reproting_ERPALIN!S:S,Reproting_ERPALIN!B:B,'Classement des produits'!A10,Reproting_ERPALIN!N:N,">"&Parametres_Dates!$B$2,Reproting_ERPALIN!$N:$N,"<="&Parametres_Dates!$B$3) -> 26.147857 | C10: =RANK(B10,$B$2:$B$234) -> 156
A11: 684352 | B11: =SUMIFS(Reproting_ERPALIN!S:S,Reproting_ERPALIN!B:B,'Classement des produits'!A11,Reproting_ERPALIN!N:N,">"&Parametres_Dates!$B$2,Reproting_ERPALIN!$N:$N,"<="&Parametres_Dates!$B$3) -> 149.65214 | C11: =RANK(B11,$B$2:$B$234) -> 33
A12: IN-09X25 | B12: =SUMIFS(Reproting_ERPALIN!S:S,Reproting_ERPALIN!B:B,'Classement des produits'!A12,Reproting_ERPALIN!N:N,">"&Parametres_Dates!$B$2,Reproting_ERPALIN!$N:$N,"<="&Parametres_Dates!$B$3) -> 187.14167 | C12: =RANK(B12,$B$2:$B$234) -> 27
